<?xml version="1.0" encoding="utf-8" ?>
<!-- =================================================================================== -->
<!-- |    This document was autogenerated by xacro from /home/ros/kuka_ws/src/kuka_ros/kr160/urdf/kr160.xacro | -->
<!-- |    EDITING THIS FILE BY HAND IS NOT RECOMMENDED                                 | -->
<!-- =================================================================================== -->
<robot name="kr160">
    <!-- Defining the colors used in this robot -->
    <material name="Black">
        <color rgba="0 0 0 1" />
    </material>
    <material name="White">
        <color rgba="1 1 1 1" />
    </material>
    <material name="Blue">
        <color rgba="0 0 1 1" />
    </material>
    <material name="Red">
        <color rgba="1 0 0 1" />
    </material>
    <!-- ///////////////////////////////////////   dummy link   ////////////////////////////////////////// -->
    <link name="dummy">
        <visual>
            <origin rpy="0 0 0" xyz=" 0 0 -0.02" />
            <geometry>
                <box size="5 1 0.02" />
            </geometry>
            <material name="Brown" />
        </visual>
        <collision>
            <origin rpy="0 0 0" xyz=" 0 0 -0.02" />
            <geometry>
                <box size="5 1 0.02" />
            </geometry>
        </collision>
        
<inertial>
            <mass value="500" />
            <inertia ixx="1.0" ixy="0.0" ixz="0.0" iyy="0.5" iyz="0.0" izz="1.0" />
        </inertial>

    </link>
    <link name="kr10_base_link">
        
<inertial>
            <origin rpy="0 0 0" xyz="-0.0389079126292309 -4.2959014174726E-05 0.095499912626456" />
            <mass value="12.0127122518777" />
            <inertia ixx="0.096372089081788" ixy="-0.000105055998553245" ixz="0.0056899080162169" iyy="0.13962559834333" iyz="-8.4214207924127E-06" izz="0.121027155275122" />
        </inertial>

        <visual>
            <origin rpy="0 0 0" xyz="0 0 0" />
            <geometry>
                <mesh filename="package://kr10/meshes/base_link.STL" />
            </geometry>
            <material name="">
                <color rgba="0.792156862745098 0.819607843137255 0.933333333333333 1" />
            </material>
        </visual>
        <collision>
            <origin rpy="0 0 0" xyz="0 0 0" />
            <geometry>
                <mesh filename="package://kr10/meshes/base_link.STL" />
            </geometry>
        </collision>
    </link>
    <link name="kr10_link1">
        
<inertial>
            <origin rpy="0 0 0" xyz="0.00741380480149578 0.00354552947139167 0.115715412511507" />
            <mass value="6.2751497959128" />
            <inertia ixx="0.0751893674671946" ixy="0.00504886489144856" ixz="-0.00509592816750828" iyy="0.0510924965053144" iyz="-0.001549309062334" izz="0.0562677349522946" />
        </inertial>

        <visual>
            <origin rpy="0 0 0" xyz="0 0 0" />
            <geometry>
                <mesh filename="package://kr10/meshes/link1.STL" />
            </geometry>
            <material name="">
                <color rgba="0.792156862745098 0.819607843137255 0.933333333333333 1" />
            </material>
        </visual>
        <collision>
            <origin rpy="0 0 0" xyz="0 0 0" />
            <geometry>
                <mesh filename="package://kr10/meshes/link1.STL" />
            </geometry>
        </collision>
    </link>
    <joint name="kr10_joint1" type="revolute">
        <origin rpy="0 0 0" xyz="0 0 0.217" />
        <parent link="kr10_base_link" />
        <child link="kr10_link1" />
        <axis xyz="0 0 1" />
        <limit effort="300" lower="-3" upper="3" velocity="1" />
        <dynamics damping="10.0" friction="0.0"/>
    </joint>
    <link name="kr10_link2">
        
<inertial>
            <origin rpy="0 0 0" xyz="0.112673325433516 -0.235533330268791 5.25939883689319E-05" />
            <mass value="10.0623910575082" />
            <inertia ixx="0.373446746946084" ixy="0.169218239470221" ixz="-0.000352160811815804" iyy="0.131793291732547" iyz="0.000952442844566425" izz="0.442938494752101" />
        </inertial>

        <visual>
            <origin rpy="0 0 0" xyz="0 0 0" />
            <geometry>
                <mesh filename="package://kr10/meshes/link2.STL" />
            </geometry>
            <material name="">
                <color rgba="0.792156862745098 0.819607843137255 0.933333333333333 1" />
            </material>
        </visual>
        <collision>
            <origin rpy="0 0 0" xyz="0 0 0" />
            <geometry>
                <mesh filename="package://kr10/meshes/link2.STL" />
            </geometry>
        </collision>
    </link>
    <joint name="kr10_joint2" type="revolute">
        <origin rpy="-1.5708 0 0.19801" xyz="0.025397 0.00050592 0.183" />
        <parent link="kr10_link1" />
        <child link="kr10_link2" />
        <axis xyz="0 0 -1" />
        <limit effort="300" lower="-1.4" upper="2.1" velocity="1" />
        <dynamics damping="10" friction="0.0"/>
    </joint>
    <link name="kr10_link3">
        
<inertial>
            <origin rpy="0 0 0" xyz="0.000529908025397541 0.0191760796551027 -2.4642212648307E-05" />
            <mass value="2.87413726622842" />
            <inertia ixx="0.0106153706452702" ixy="-0.000284572592443065" ixz="-3.571396350265E-06" iyy="0.00740315810462365" iyz="1.82140206105029E-06" izz="0.0111376816178918" />
        </inertial>

        <visual>
            <origin rpy="0 0 0" xyz="0 0 0" />
            <geometry>
                <mesh filename="package://kr10/meshes/link3.STL" />
            </geometry>
            <material name="">
                <color rgba="0.792156862745098 0.819607843137255 0.933333333333333 1" />
            </material>
        </visual>
        <collision>
            <origin rpy="0 0 0" xyz="0 0 0" />
            <geometry>
                <mesh filename="package://kr10/meshes/link3.STL" />
            </geometry>
        </collision>
    </link>
    <joint name="kr10_joint3" type="revolute">
        <origin rpy="-3.1416 0 1.5708" xyz="0.25768 -0.49719 0.0035" />
        <parent link="kr10_link2" />
        <child link="kr10_link3" />
        <axis xyz="0 0 -1" />
        <limit effort="300" lower="-4" upper="1" velocity="1" />
        <dynamics damping="10" friction="0.0"/>
    </joint>
    <link name="kr10_link4">
        
<inertial>
            <origin rpy="0 0 0" xyz="0.000495827295870943 0.000331263303056328 0.185104333291848" />
            <mass value="4.03623874477417" />
            <inertia ixx="0.0514724229213813" ixy="-0.000345898984168441" ixz="-7.55534798658624E-05" iyy="0.0508207618372116" iyz="-0.000225438428481011" izz="0.00734338590437416" />
        </inertial>

        <visual>
            <origin rpy="0 0 0" xyz="0 0 0" />
            <geometry>
                <mesh filename="package://kr10/meshes/link4.STL" />
            </geometry>
            <material name="">
                <color rgba="0.792156862745098 0.819607843137255 0.933333333333333 1" />
            </material>
        </visual>
        <collision>
            <origin rpy="0 0 0" xyz="0 0 0" />
            <geometry>
                <mesh filename="package://kr10/meshes/link4.STL" />
            </geometry>
        </collision>
    </link>
    <joint name="kr10_joint4" type="continuous">
        <origin rpy="1.5708 -0.33893 2.5361" xyz="0.037811 0.11612 0" />
        <parent link="kr10_link3" />
        <child link="kr10_link4" />
        <axis xyz="0 0 -1" />
        <dynamics damping="5" friction="0.0"/>
    </joint>
    <link name="kr10_link5">
        
<inertial>
            <origin rpy="0 0 0" xyz="0.0120557743377237 0.0101959936253579 0.0021636985615841" />
            <mass value="0.4420683299725" />
            <inertia ixx="0.000419965604922443" ixy="-0.000120215358737915" ixz="1.29271922535509E-05" iyy="0.00046073941946462" iyz="1.04681508421518E-05" izz="0.000528480867675673" />
        </inertial>

        <visual>
            <origin rpy="0 0 0" xyz="0 0 0" />
            <geometry>
                <mesh filename="package://kr10/meshes/link5.STL" />
            </geometry>
            <material name="">
                <color rgba="0.792156862745098 0.819607843137255 0.933333333333333 1" />
            </material>
        </visual>
        <collision>
            <origin rpy="0 0 0" xyz="0 0 0" />
            <geometry>
                <mesh filename="package://kr10/meshes/link5.STL" />
            </geometry>
        </collision>
    </link>
    <joint name="kr10_joint5" type="revolute">
        <origin rpy="1.5708 -0.97526 -0.39435" xyz="9.6051E-05 0.00023081 0.398" />
        <parent link="kr10_link4" />
        <child link="kr10_link5" />
        <axis xyz="0 0 -1" />
        <limit effort="300" lower="-1.8" upper="2.1" velocity="1" />
        <dynamics damping="1" friction="0.0"/>
    </joint>
    <link name="kr10_link6">
        
<inertial>
            <origin rpy="0 0 0" xyz="-2.27839703337285E-06 -1.67395761618838E-06 0.0553153630699634" />
            <mass value="0.213549096503453" />
            <inertia ixx="0.000219860024372743" ixy="-4.50770251278094E-09" ixz="-2.33140665193661E-08" iyy="0.000219862847887346" iyz="-1.71290426984171E-08" izz="7.43113458858691E-05" />
        </inertial>

        <visual>
            <origin rpy="0 0 0" xyz="0 0 0" />
            <geometry>
                <mesh filename="package://kr10/meshes/link6.STL" />
            </geometry>
            <material name="">
                <color rgba="0.792156862745098 0.819607843137255 0.933333333333333 1" />
            </material>
        </visual>
        <collision>
            <origin rpy="0 0 0" xyz="0 0 0" />
            <geometry>
                <mesh filename="package://kr10/meshes/link6.STL" />
            </geometry>
        </collision>
    </link>
    <joint name="kr10_joint6" type="continuous">
        <origin rpy="-1.5708 0.34761 -0.87071" xyz="0.050858 0.042845 0.00025" />
        <parent link="kr10_link5" />
        <child link="kr10_link6" />
        <axis xyz="0 0 1" />
        <dynamics damping="1" friction="0.0"/>
    </joint>
    <joint name="dummy_joint_kr10" type="fixed">
        <origin rpy="0 0 0" xyz="-1.5 0 0" />
        <parent link="dummy" />
        <child link="kr10_base_link" />
    </joint>
    <link name="kr60_base_link">
        
<inertial>
            <origin rpy="0 0 0" xyz="-0.0435912921701559 0.000713255348429254 0.235869111604986" />
            <mass value="131.03709830541" />
            <inertia ixx="4.89785584702139" ixy="0.0374706691148856" ixz="-0.212225957715894" iyy="6.14888362749998" iyz="-0.000661186598210806" izz="6.05287659150192" />
        </inertial>

        <visual>
            <origin rpy="0 0 0" xyz="0 0 0" />
            <geometry>
                <mesh filename="package://kr60/meshes/base_link.STL" />
            </geometry>
            <material name="">
                <color rgba="0.223529411764706 0.223529411764706 0.223529411764706 1" />
            </material>
        </visual>
        <collision>
            <origin rpy="0 0 0" xyz="0 0 0" />
            <geometry>
                <mesh filename="package://kr60/meshes/base_link.STL" />
            </geometry>
        </collision>
    </link>
    <link name="kr60_link1">
        
<inertial>
            <origin rpy="0 0 0" xyz="0.140797971765356 -0.0164096960535733 0.187359043807774" />
            <mass value="82.8920172367664" />
            <inertia ixx="2.45467046863107" ixy="0.256865903550409" ixz="-1.16906897181984" iyy="4.32241124955131" iyz="0.176354317999072" izz="4.14782926078883" />
        </inertial>

        <visual>
            <origin rpy="0 0 0" xyz="0 0 0" />
            <geometry>
                <mesh filename="package://kr60/meshes/link1.STL" />
            </geometry>
            <material name="">
                <color rgba="0.2 0.2 0.2 1" />
            </material>
        </visual>
        <collision>
            <origin rpy="0 0 0" xyz="0 0 0" />
            <geometry>
                <mesh filename="package://kr60/meshes/link1.STL" />
            </geometry>
        </collision>
    </link>
    <joint name="kr60_joint1" type="revolute">
        <origin rpy="0 0 0" xyz="0.00035187 -4.2629E-05 0.49797" />
        <parent link="kr60_base_link" />
        <child link="kr60_link1" />
        <axis xyz="0 0 -1" />
        <limit effort="300" lower="-3.14" upper="3.14" velocity="1" />
        <dynamics damping="50.0" friction="0.0"/>
    </joint>
    <link name="kr60_link2">
        
<inertial>
            <origin rpy="0 0 0" xyz="0.251956440024243 0.31201537254992 0.101340677761361" />
            <mass value="54.5098631728848" />
            <inertia ixx="3.37106903827733" ixy="-2.31897616562626" ixz="-0.0123248243600918" iyy="2.37820274493385" iyz="-0.0168099695812892" izz="5.37880440302274" />
        </inertial>

        <visual>
            <origin rpy="0 0 0" xyz="0 0 0" />
            <geometry>
                <mesh filename="package://kr60/meshes/link2.STL" />
            </geometry>
            <material name="">
                <color rgba="0.2 0.2 0.2 1" />
            </material>
        </visual>
        <collision>
            <origin rpy="0 0 0" xyz="0 0 0" />
            <geometry>
                <mesh filename="package://kr60/meshes/link2.STL" />
            </geometry>
        </collision>
    </link>
    <joint name="kr60_joint2" type="revolute">
        <origin rpy="1.5708 0 -0.22752" xyz="0.30771 -0.22264 0.31103" />
        <parent link="kr60_link1" />
        <child link="kr60_link2" />
        <axis xyz="0 0 -1" />
        <limit effort="300" lower="-1.2" upper="1.4" velocity="1" />
        <dynamics damping="20.0" friction="0.0"/>
    </joint>
    <link name="kr60_link3">
        
<inertial>
            <origin rpy="0 0 0" xyz="0.0264574349222555 0.0622817405350231 -0.184769381740328" />
            <mass value="52.8139839675299" />
            <inertia ixx="1.44583618573615" ixy="0.675569358504738" ixz="-0.08105662717627" iyy="1.74771111138366" iyz="0.138955152142587" izz="2.35512831766369" />
        </inertial>

        <visual>
            <origin rpy="0 0 0" xyz="0 0 0" />
            <geometry>
                <mesh filename="package://kr60/meshes/link3.STL" />
            </geometry>
            <material name="">
                <color rgba="0.2 0.2 0.2 1" />
            </material>
        </visual>
        <collision>
            <origin rpy="0 0 0" xyz="0 0 0" />
            <geometry>
                <mesh filename="package://kr60/meshes/link3.STL" />
            </geometry>
        </collision>
    </link>
    <joint name="kr60_joint3" type="revolute">
        <origin rpy="0 0 0" xyz="0.53484 0.66064 0.017" />
        <parent link="kr60_link2" />
        <child link="kr60_link3" />
        <axis xyz="0 0 -1" />
        <limit effort="300" lower="-4" upper="1.1" velocity="1" />
        <dynamics damping="10.0" friction="0.0"/>
    </joint>
    <link name="kr60_link4">
        
<inertial>
            <origin rpy="0 0 0" xyz="-0.00407295592284429 0.0114233456063895 0.191771095925468" />
            <mass value="9.33484403440081" />
            <inertia ixx="0.173337740682456" ixy="0.00766249996810709" ixz="0.00211297471780549" iyy="0.155598279375636" iyz="-0.00570657719860746" izz="0.0550237588439791" />
        </inertial>

        <visual>
            <origin rpy="0 0 0" xyz="0 0 0" />
            <geometry>
                <mesh filename="package://kr60/meshes/link4.STL" />
            </geometry>
            <material name="">
                <color rgba="0.2 0.2 0.2 1" />
            </material>
        </visual>
        <collision>
            <origin rpy="0 0 0" xyz="0 0 0" />
            <geometry>
                <mesh filename="package://kr60/meshes/link4.STL" />
            </geometry>
        </collision>
    </link>
    <joint name="kr60_joint4" type="revolute">
        <origin rpy="1.5708 0.35122 0.88684" xyz="0.40937 -0.14672 -0.16457" />
        <parent link="kr60_link3" />
        <child link="kr60_link4" />
        <axis xyz="0 0 -1" />
        <limit effort="300" lower="-3.14" upper="3.14" velocity="1" />
        <dynamics damping="10.0" friction="0.0"/>
    </joint>
    <link name="kr60_link5">
        
<inertial>
            <origin rpy="0 0 0" xyz="-0.00305829815751446 -0.0262624932024078 -0.0855135194075107" />
            <mass value="3.88136296388639" />
            <inertia ixx="0.018435030823998" ixy="-0.000643999611295686" ixz="0.000225940311804447" iyy="0.0129804584036509" iyz="0.00194018831589403" izz="0.0166999744136098" />
        </inertial>

        <visual>
            <origin rpy="0 0 0" xyz="0 0 0" />
            <geometry>
                <mesh filename="package://kr60/meshes/link5.STL" />
            </geometry>
            <material name="">
                <color rgba="0.2 0.2 0.2 1" />
            </material>
        </visual>
        <collision>
            <origin rpy="0 0 0" xyz="0 0 0" />
            <geometry>
                <mesh filename="package://kr60/meshes/link5.STL" />
            </geometry>
        </collision>
    </link>
    <joint name="kr60_joint5" type="revolute">
        <origin rpy="-1.5708 -0.88729 0.35371" xyz="-0.023643 0.06437 0.41596" />
        <parent link="kr60_link4" />
        <child link="kr60_link5" />
        <axis xyz="0 0 -1" />
        <limit effort="300" lower="-3.2" upper="1.52" velocity="1" />
        <dynamics damping="5.0" friction="0.0"/>
    </joint>
    <link name="kr60_link6">
        
<inertial>
            <origin rpy="0 0 0" xyz="-0.000266811986394 0.0022051066231592 0.159155225523868" />
            <mass value="2.49283147388058" />
            <inertia ixx="0.0228945331943247" ixy="6.35070513466885E-05" ixz="-3.49749616928972E-05" iyy="0.0225138449320645" iyz="0.000268449006240413" izz="0.0064716945834193" />
        </inertial>

        <visual>
            <origin rpy="0 0 0" xyz="0 0 0" />
            <geometry>
                <mesh filename="package://kr60/meshes/link6.STL" />
            </geometry>
            <material name="">
                <color rgba="0.223529411764706 0.223529411764706 0.223529411764706 1" />
            </material>
        </visual>
        <collision>
            <origin rpy="0 0 0" xyz="0 0 0" />
            <geometry>
                <mesh filename="package://kr60/meshes/link6.STL" />
            </geometry>
        </collision>
    </link>
    <joint name="kr60_joint6" type="revolute">
        <origin rpy="1.5708 0.23058 -0.11592" xyz="-0.014573 -0.12469 -0.068374" />
        <parent link="kr60_link5" />
        <child link="kr60_link6" />
        <axis xyz="0 0 -1" />
        <limit effort="300" lower="-3.14" upper="3.14" velocity="1" />
        <dynamics damping="1.0" friction="0.0"/>
    </joint>
    <!-- //////////////////////////////////////   finger   ////////////////////////////////////////////// -->
    <link name="kr60_finger_link1">
        
<inertial>
            <origin rpy="0 0 0" xyz="-0.0749733532255245 0.130628735923085 -0.074999999999946" />
            <mass value="0.893519309367383" />
            <inertia ixx="0.0073937480635528" ixy="0.00124957233576088" ixz="3.13158244995282E-16" iyy="0.00326091528208565" iyz="-4.25684877972121E-16" izz="0.00565771627211372" />
        </inertial>

        <visual>
            <origin rpy="0 0 0" xyz="0 0 0" />
            <geometry>
                <mesh filename="package://kr60/meshes/finger_link1.STL" />
            </geometry>
            <material name="">
                <color rgba="1 1 1 1" />
            </material>
        </visual>
        <collision>
            <origin rpy="0 0 0" xyz="0 0 0" />
            <geometry>
                <mesh filename="package://kr60/meshes/finger_link1.STL" />
            </geometry>
        </collision>
    </link>
    <joint name="kr60_finger_joint1" type="revolute">
        <origin rpy="1.5708 0.39611 -1.2963" xyz="-0.093833 0.056587 0.2565" />
        <parent link="kr60_link6" />
        <child link="kr60_finger_link1" />
        <axis xyz="0 0 -1" />
        <limit effort="300" lower="-1" upper="0.2" velocity="1" />
        <dynamics damping="1.0" friction="0.0"/>
    </joint>
    <link name="kr60_finger_link2">
        
<inertial>
            <origin rpy="0 0 0" xyz="-0.0434409829659067 0.144196411218408 -0.0750000000000308" />
            <mass value="0.893519309367395" />
            <inertia ixx="0.00645658292905761" ixy="0.00213264017844388" ixz="-9.93129189996722E-17" iyy="0.00419586853440302" iyz="5.19170210294684E-16" izz="0.00565550438993584" />
        </inertial>

        <visual>
            <origin rpy="0 0 0" xyz="0 0 0" />
            <geometry>
                <mesh filename="package://kr60/meshes/finger_link2.STL" />
            </geometry>
            <material name="">
                <color rgba="1 1 1 1" />
            </material>
        </visual>
        <collision>
            <origin rpy="0 0 0" xyz="0 0 0" />
            <geometry>
                <mesh filename="package://kr60/meshes/finger_link2.STL" />
            </geometry>
        </collision>
    </link>
    <joint name="kr60_finger_joint2" type="revolute">
        <origin rpy="1.5708 0.39611 -1.2963" xyz="-0.050462 -0.097423 0.2565" />
        <parent link="kr60_link6" />
        <child link="kr60_finger_link2" />
        <axis xyz="0 0 1" />
        <limit effort="300" lower="-1" upper="0.2" velocity="1" />
        <dynamics damping="1.0" friction="0.0"/>
    </joint>
    <!-- Grasping frame -->
    <link name="kr60_finger_frame" />
    <joint name="kr60_finger_frame_joint" type="fixed">
        <parent link="kr60_link6" />
        <child link="kr60_finger_frame" />
        <origin rpy="0 0 0" xyz="0.08 0 0" />
    </joint>
    <joint name="dummy_joint_kr60" type="fixed">
        <origin rpy="0 0 3.14" xyz="1.5 0 0" />
        <parent link="dummy" />
        <child link="kr60_base_link" />
    </joint>
    
<transmission name="tran1">
        <type>transmission_interface/SimpleTransmission</type>
        <joint name="kr10_joint1">
            <hardwareInterface>hardware_interface/PositionJointInterface</hardwareInterface>
        </joint>
        <actuator name="motor1">
            <hardwareInterface>hardware_interface/PositionJointInterface</hardwareInterface>
            <mechanicalReduction>1</mechanicalReduction>
        </actuator>
    </transmission>
    <transmission name="tran1">
        <type>transmission_interface/SimpleTransmission</type>
        <joint name="kr10_joint2">
            <hardwareInterface>hardware_interface/PositionJointInterface</hardwareInterface>
        </joint>
        <actuator name="motor1">
            <hardwareInterface>hardware_interface/PositionJointInterface</hardwareInterface>
            <mechanicalReduction>1</mechanicalReduction>
        </actuator>
    </transmission>
    <transmission name="tran1">
        <type>transmission_interface/SimpleTransmission</type>
        <joint name="kr10_joint3">
            <hardwareInterface>hardware_interface/PositionJointInterface</hardwareInterface>
        </joint>
        <actuator name="motor1">
            <hardwareInterface>hardware_interface/PositionJointInterface</hardwareInterface>
            <mechanicalReduction>1</mechanicalReduction>
        </actuator>
    </transmission>
    <transmission name="tran1">
        <type>transmission_interface/SimpleTransmission</type>
        <joint name="kr10_joint4">
            <hardwareInterface>hardware_interface/PositionJointInterface</hardwareInterface>
        </joint>
        <actuator name="motor1">
            <hardwareInterface>hardware_interface/PositionJointInterface</hardwareInterface>
            <mechanicalReduction>1</mechanicalReduction>
        </actuator>
    </transmission>
    <transmission name="tran1">
        <type>transmission_interface/SimpleTransmission</type>
        <joint name="kr10_joint5">
            <hardwareInterface>hardware_interface/PositionJointInterface</hardwareInterface>
        </joint>
        <actuator name="motor1">
            <hardwareInterface>hardware_interface/PositionJointInterface</hardwareInterface>
            <mechanicalReduction>1</mechanicalReduction>
        </actuator>
    </transmission>
    <transmission name="tran1">
        <type>transmission_interface/SimpleTransmission</type>
        <joint name="kr10_joint6">
            <hardwareInterface>hardware_interface/PositionJointInterface</hardwareInterface>
        </joint>
        <actuator name="motor1">
            <hardwareInterface>hardware_interface/PositionJointInterface</hardwareInterface>
            <mechanicalReduction>1</mechanicalReduction>
        </actuator>
    </transmission>
    <transmission name="tran1">
        <type>transmission_interface/SimpleTransmission</type>
        <joint name="kr60_joint1">
            <hardwareInterface>hardware_interface/PositionJointInterface</hardwareInterface>
        </joint>
        <actuator name="motor1">
            <hardwareInterface>hardware_interface/PositionJointInterface</hardwareInterface>
            <mechanicalReduction>1</mechanicalReduction>
        </actuator>
    </transmission>
    <transmission name="tran1">
        <type>transmission_interface/SimpleTransmission</type>
        <joint name="kr60_joint2">
            <hardwareInterface>hardware_interface/PositionJointInterface</hardwareInterface>
        </joint>
        <actuator name="motor1">
            <hardwareInterface>hardware_interface/PositionJointInterface</hardwareInterface>
            <mechanicalReduction>1</mechanicalReduction>
        </actuator>
    </transmission>
    <transmission name="tran1">
        <type>transmission_interface/SimpleTransmission</type>
        <joint name="kr60_joint3">
            <hardwareInterface>hardware_interface/PositionJointInterface</hardwareInterface>
        </joint>
        <actuator name="motor1">
            <hardwareInterface>hardware_interface/PositionJointInterface</hardwareInterface>
            <mechanicalReduction>1</mechanicalReduction>
        </actuator>
    </transmission>
    <transmission name="tran1">
        <type>transmission_interface/SimpleTransmission</type>
        <joint name="kr60_joint4">
            <hardwareInterface>hardware_interface/PositionJointInterface</hardwareInterface>
        </joint>
        <actuator name="motor1">
            <hardwareInterface>hardware_interface/PositionJointInterface</hardwareInterface>
            <mechanicalReduction>1</mechanicalReduction>
        </actuator>
    </transmission>
    <transmission name="tran1">
        <type>transmission_interface/SimpleTransmission</type>
        <joint name="kr60_joint5">
            <hardwareInterface>hardware_interface/PositionJointInterface</hardwareInterface>
        </joint>
        <actuator name="motor1">
            <hardwareInterface>hardware_interface/PositionJointInterface</hardwareInterface>
            <mechanicalReduction>1</mechanicalReduction>
        </actuator>
    </transmission>
    <transmission name="tran1">
        <type>transmission_interface/SimpleTransmission</type>
        <joint name="kr60_joint6">
            <hardwareInterface>hardware_interface/PositionJointInterface</hardwareInterface>
        </joint>
        <actuator name="motor1">
            <hardwareInterface>hardware_interface/PositionJointInterface</hardwareInterface>
            <mechanicalReduction>1</mechanicalReduction>
        </actuator>
    </transmission>
    <transmission name="tran1">
        <type>transmission_interface/SimpleTransmission</type>
        <joint name="kr60_finger_joint1">
            <hardwareInterface>hardware_interface/PositionJointInterface</hardwareInterface>
        </joint>
        <actuator name="motor1">
            <hardwareInterface>hardware_interface/PositionJointInterface</hardwareInterface>
            <mechanicalReduction>1</mechanicalReduction>
        </actuator>
    </transmission>
    <transmission name="tran1">
        <type>transmission_interface/SimpleTransmission</type>
        <joint name="kr60_finger_joint2">
            <hardwareInterface>hardware_interface/PositionJointInterface</hardwareInterface>
        </joint>
        <actuator name="motor1">
            <hardwareInterface>hardware_interface/PositionJointInterface</hardwareInterface>
            <mechanicalReduction>1</mechanicalReduction>
        </actuator>
    </transmission>
    <!-- ros_control plugin -->
    <gazebo>
        <plugin filename="libgazebo_ros_control.so" name="gazebo_ros_control">
            <robotNamespace>/kr160</robotNamespace>
            <robotSimType>gazebo_ros_control/DefaultRobotHWSim</robotSimType>
            <legacyModeNS>true</legacyModeNS>
        </plugin>
    </gazebo>
    <!-- default joint position -->
    <!-- kr10: -0.17 0.28 -0.55 0.00 -1.35 -0.01 -->
    <!-- kr60: -0.21 0.38 0.01 0.09 -2.35 0.00 0.00 0.00 -->
    <!-- cylinders -->
    <!-- cylinder0: 0.1 0.05-->
    <!-- cylinder1: 0.15 0.3 -->
    <transmission name="trans_kr10_joint1">
        <type>transmission_interface/SimpleTransmission</type>
        <joint name="kr10_joint1">
            <hardwareInterface>hardware_interface/PositionJointInterface</hardwareInterface>
        </joint>
        <actuator name="kr10_joint1_motor">
            <hardwareInterface>hardware_interface/PositionJointInterface</hardwareInterface>
            <mechanicalReduction>1</mechanicalReduction>
        </actuator>
    </transmission>
    <transmission name="trans_kr10_joint2">
        <type>transmission_interface/SimpleTransmission</type>
        <joint name="kr10_joint2">
            <hardwareInterface>hardware_interface/PositionJointInterface</hardwareInterface>
        </joint>
        <actuator name="kr10_joint2_motor">
            <hardwareInterface>hardware_interface/PositionJointInterface</hardwareInterface>
            <mechanicalReduction>1</mechanicalReduction>
        </actuator>
    </transmission>
    <transmission name="trans_kr10_joint3">
        <type>transmission_interface/SimpleTransmission</type>
        <joint name="kr10_joint3">
            <hardwareInterface>hardware_interface/PositionJointInterface</hardwareInterface>
        </joint>
        <actuator name="kr10_joint3_motor">
            <hardwareInterface>hardware_interface/PositionJointInterface</hardwareInterface>
            <mechanicalReduction>1</mechanicalReduction>
        </actuator>
    </transmission>
    <transmission name="trans_kr10_joint4">
        <type>transmission_interface/SimpleTransmission</type>
        <joint name="kr10_joint4">
            <hardwareInterface>hardware_interface/PositionJointInterface</hardwareInterface>
        </joint>
        <actuator name="kr10_joint4_motor">
            <hardwareInterface>hardware_interface/PositionJointInterface</hardwareInterface>
            <mechanicalReduction>1</mechanicalReduction>
        </actuator>
    </transmission>
    <transmission name="trans_kr10_joint5">
        <type>transmission_interface/SimpleTransmission</type>
        <joint name="kr10_joint5">
            <hardwareInterface>hardware_interface/PositionJointInterface</hardwareInterface>
        </joint>
        <actuator name="kr10_joint5_motor">
            <hardwareInterface>hardware_interface/PositionJointInterface</hardwareInterface>
            <mechanicalReduction>1</mechanicalReduction>
        </actuator>
    </transmission>
    <transmission name="trans_kr10_joint6">
        <type>transmission_interface/SimpleTransmission</type>
        <joint name="kr10_joint6">
            <hardwareInterface>hardware_interface/PositionJointInterface</hardwareInterface>
        </joint>
        <actuator name="kr10_joint6_motor">
            <hardwareInterface>hardware_interface/PositionJointInterface</hardwareInterface>
            <mechanicalReduction>1</mechanicalReduction>
        </actuator>
    </transmission>
    <transmission name="trans_kr60_joint1">
        <type>transmission_interface/SimpleTransmission</type>
        <joint name="kr60_joint1">
            <hardwareInterface>hardware_interface/PositionJointInterface</hardwareInterface>
        </joint>
        <actuator name="kr60_joint1_motor">
            <hardwareInterface>hardware_interface/PositionJointInterface</hardwareInterface>
            <mechanicalReduction>1</mechanicalReduction>
        </actuator>
    </transmission>
    <transmission name="trans_kr60_joint2">
        <type>transmission_interface/SimpleTransmission</type>
        <joint name="kr60_joint2">
            <hardwareInterface>hardware_interface/PositionJointInterface</hardwareInterface>
        </joint>
        <actuator name="kr60_joint2_motor">
            <hardwareInterface>hardware_interface/PositionJointInterface</hardwareInterface>
            <mechanicalReduction>1</mechanicalReduction>
        </actuator>
    </transmission>
    <transmission name="trans_kr60_joint3">
        <type>transmission_interface/SimpleTransmission</type>
        <joint name="kr60_joint3">
            <hardwareInterface>hardware_interface/PositionJointInterface</hardwareInterface>
        </joint>
        <actuator name="kr60_joint3_motor">
            <hardwareInterface>hardware_interface/PositionJointInterface</hardwareInterface>
            <mechanicalReduction>1</mechanicalReduction>
        </actuator>
    </transmission>
    <transmission name="trans_kr60_joint4">
        <type>transmission_interface/SimpleTransmission</type>
        <joint name="kr60_joint4">
            <hardwareInterface>hardware_interface/PositionJointInterface</hardwareInterface>
        </joint>
        <actuator name="kr60_joint4_motor">
            <hardwareInterface>hardware_interface/PositionJointInterface</hardwareInterface>
            <mechanicalReduction>1</mechanicalReduction>
        </actuator>
    </transmission>
    <transmission name="trans_kr60_joint5">
        <type>transmission_interface/SimpleTransmission</type>
        <joint name="kr60_joint5">
            <hardwareInterface>hardware_interface/PositionJointInterface</hardwareInterface>
        </joint>
        <actuator name="kr60_joint5_motor">
            <hardwareInterface>hardware_interface/PositionJointInterface</hardwareInterface>
            <mechanicalReduction>1</mechanicalReduction>
        </actuator>
    </transmission>
    <transmission name="trans_kr60_joint6">
        <type>transmission_interface/SimpleTransmission</type>
        <joint name="kr60_joint6">
            <hardwareInterface>hardware_interface/PositionJointInterface</hardwareInterface>
        </joint>
        <actuator name="kr60_joint6_motor">
            <hardwareInterface>hardware_interface/PositionJointInterface</hardwareInterface>
            <mechanicalReduction>1</mechanicalReduction>
        </actuator>
    </transmission>
    <transmission name="trans_kr60_finger_joint1">
        <type>transmission_interface/SimpleTransmission</type>
        <joint name="kr60_finger_joint1">
            <hardwareInterface>hardware_interface/PositionJointInterface</hardwareInterface>
        </joint>
        <actuator name="kr60_finger_joint1_motor">
            <hardwareInterface>hardware_interface/PositionJointInterface</hardwareInterface>
            <mechanicalReduction>1</mechanicalReduction>
        </actuator>
    </transmission>
    <transmission name="trans_kr60_finger_joint2">
        <type>transmission_interface/SimpleTransmission</type>
        <joint name="kr60_finger_joint2">
            <hardwareInterface>hardware_interface/PositionJointInterface</hardwareInterface>
        </joint>
        <actuator name="kr60_finger_joint2_motor">
            <hardwareInterface>hardware_interface/PositionJointInterface</hardwareInterface>
            <mechanicalReduction>1</mechanicalReduction>
        </actuator>
    </transmission>
    <!-- <gazebo>
        <plugin name="gazebo_ros_control" filename="libgazebo_ros_control.so">
            <robotNamespace>/kr160</robotNamespace>
        </plugin>
    </gazebo> -->
</robot>
